<?xml version="1.0"?>
<robot name="hanging_object">

    <!-- Fixed base at the ceiling -->
    <link name="base_1">
        <visual>
            <origin xyz="0 0 0" rpy="0 0 0"/>
            <geometry>
                <box size="0.2 0.2 0.1"/>
            </geometry>
            <material name="grey">
                <color rgba="0.5 0.5 0.5 1"/>
            </material>
        </visual>
        <collision>
            <origin xyz="0 0 0" rpy="0 0 0"/>
            <geometry>
                <box size="0.2 0.2 0.1"/>
            </geometry>
        </collision>
        <inertial>
            <mass value="0"/>
            <inertia ixx="0" iyy="0" izz="0" ixy="0" ixz="0" iyz="0"/>
        </inertial>
    </link>

    <!-- Intermediate link for first rotation (X-axis) -->
    <link name="x_rotation_link_1">
        <inertial>
            <mass value="0"/>
            <inertia ixx="0" iyy="0" izz="0" ixy="0" ixz="0" iyz="0"/>
        </inertial>
    </link>

    <!-- Intermediate link for second rotation (Y-axis) -->
    <link name="y_rotation_link_1">
        <inertial>
            <mass value="0"/>
            <inertia ixx="0" iyy="0" izz="0" ixy="0" ixz="0" iyz="0"/>
        </inertial>
    </link>

    <!-- Hanging link with smaller intersection -->
    <link name="hanging_link_1">
        <visual>
            <origin xyz="0 0 -0.325" rpy="0 0 0"/>
            <geometry>
                <cylinder radius="0.005" length="0.65"/>
            </geometry>
            <material name="black">
                <color rgba="0 0 0 1"/>
            </material>
        </visual>
        <collision>
            <origin xyz="0 0 -0.325" rpy="0 0 0"/>
            <geometry>
                <cylinder radius="0.005" length="0.65"/>
            </geometry>
        </collision>
        <inertial>
            <mass value="0"/>
            <origin xyz="0 0 0"/>
            <inertia ixx="0" iyy="0" izz="0" ixy="0" ixz="0" iyz="0"/>
        </inertial>
    </link>

    <!-- Bucket link -->
    <link name="bucket_1">
        <visual>
            <origin xyz="0 0 -0.11" rpy="0 0 0"/>
            <geometry>
                <cylinder radius="0.115" length="0.22"/>
            </geometry>
            <material name="green">
                <color rgba="0.0 1.0 0.0 1"/>
            </material>
        </visual>
        <collision>
            <origin xyz="0 0 -0.11" rpy="0 0 0"/>
            <geometry>
                <cylinder radius="0.115" length="0.22"/>
            </geometry>
        </collision>
        <inertial>
            <mass value="5.6"/>
            <origin xyz="0 0 -0.073"/>
            <inertia ixx="0.05" iyy="0.05" izz="0.05" ixy="0" ixz="0" iyz="0"/>
        </inertial>
    </link>

    <!-- Revolute joint for X-axis rotation -->
    <joint name="x_rotation_joint_1" type="revolute">
        <parent link="base_1"/>
        <child link="x_rotation_link_1"/>
        <origin xyz="0 0 0"/>
        <axis xyz="1 0 0"/>
        <limit lower="-3.14" upper="3.14" effort="10" velocity="1"/>
        <dynamics damping="0.0" friction="0.0"/>
    </joint>

    <!-- Revolute joint for Y-axis rotation -->
    <joint name="y_rotation_joint_1" type="revolute">
        <parent link="x_rotation_link_1"/>
        <child link="y_rotation_link_1"/>
        <origin xyz="0 0 0"/>
        <axis xyz="0 1 0"/>
        <limit lower="-3.14" upper="3.14" effort="10" velocity="1"/>
        <dynamics damping="0.0" friction="0.0"/>
    </joint>

    <!-- Revolute joint for Z-axis rotation -->
    <joint name="z_rotation_joint_1" type="revolute">
        <parent link="y_rotation_link_1"/>
        <child link="hanging_link_1"/>
        <origin xyz="0 0 0"/>
        <axis xyz="0 0 1"/>
        <limit lower="-3.14" upper="3.14" effort="10" velocity="1"/>
        <dynamics damping="0.0" friction="0.0"/>
    </joint>

    <!-- Fixed joint for bucket -->
    <joint name="bucket_joint_1" type="fixed">
        <parent link="hanging_link_1"/>
        <child link="bucket_1"/>
        <origin xyz="0 0 -0.65"/>
    </joint>

  <link name="world">
    <inertial>
      <mass value="0"/>
      <inertia ixx="0.0" ixy="0.0" ixz="0.0" iyy="0.0" iyz="0.0" izz="0.0"/>
    </inertial>
  </link>
  <joint name="fixed_joint_1" type="fixed">
    <parent link="world"/>
    <child link="base_1"/>
  </joint>
</robot>