<?xml version="1.0" ?>
<!-- =================================================================================== -->
<!-- |    This document was autogenerated by xacro from /home/docker/kuka_ws/src/iiwa_bhand/iiwa_bhand_description/robots/iiwa7_bhand.urdf.xacro | -->
<!-- |    EDITING THIS FILE BY HAND IS NOT RECOMMENDED                                 | -->
<!-- =================================================================================== -->
<robot name="iiwa7">
  <material name="Black">
    <color rgba="0.0 0.0 0.0 1.0"/>
  </material>
  <material name="Blue">
    <color rgba="0.0 0.0 0.8 1.0"/>
  </material>
  <material name="Green">
    <color rgba="0.0 0.8 0.0 1.0"/>
  </material>
  <material name="Grey">
    <color rgba="0.4 0.4 0.4 1.0"/>
  </material>
  <material name="Orange">
    <color rgba="1.0 0.4235294117647059 0.0392156862745098 1.0"/>
  </material>
  <material name="Brown">
    <color rgba="0.8705882352941177 0.8117647058823529 0.7647058823529411 1.0"/>
  </material>
  <material name="Red">
    <color rgba="0.8 0.0 0.0 1.0"/>
  </material>
  <material name="White">
    <color rgba="1.0 1.0 1.0 1.0"/>
  </material>
  <!-- Fix to world just for testing -->
  <link name="world">
        <inertial>
      <origin rpy="0 0 0" xyz="0 0 0"/>
      <mass value="0"/>
      <inertia ixx="0" ixy="0" ixz="0" iyy="0" iyz="0" izz="0"/>
    </inertial>
  </link>
  <!--joint between {parent} and link_0-->
  <joint name="world_iiwa_joint" type="fixed">
    <origin rpy="0 0 0" xyz="0 0 0"/>
    <parent link="world"/>
    <child link="iiwa_link_0"/>
  </joint>
  <link name="iiwa_link_0">
    <inertial>
      <origin rpy="0 0 0" xyz="-0.1 0 0.07"/>
      <mass value="5"/>
      <inertia ixx="0.05" ixy="0" ixz="0" iyy="0.06" iyz="0" izz="0.03"/>
    </inertial>
    <visual>
      <origin rpy="0 0 0" xyz="0 0 0"/>
      <geometry>
        <mesh filename="package://iiwa_description/meshes/iiwa7/visual/link_0.obj"/>
      </geometry>
      <material name="Grey"/>
    </visual>
    <collision>
      <origin rpy="0 0 0" xyz="0 0 0"/>
      <geometry>
        <mesh filename="package://iiwa_description/meshes/iiwa7/collision/link_0.obj"/>
      </geometry>
      <material name="Grey"/>
    </collision>
    <self_collision_checking>
      <origin rpy="0 0 0" xyz="0 0 0"/>
      <geometry>
        <capsule length="0.25" radius="0.15"/>
      </geometry>
    </self_collision_checking>
  </link>
  <!-- joint between link_0 and link_1 -->
  <joint name="iiwa_joint_1" type="revolute">
    <parent link="iiwa_link_0"/>
    <child link="iiwa_link_1"/>
    <origin rpy="0 0 0" xyz="0 0 0.15"/>
    <axis xyz="0 0 1"/>
    <limit effort="300" lower="-2.9670597283903604" upper="2.9670597283903604" velocity="10"/>
    <safety_controller k_position="100" k_velocity="2" soft_lower_limit="-2.9321531433504737" soft_upper_limit="2.9321531433504737"/>
    <dynamics damping="0.5"/>
  </joint>
  <link name="iiwa_link_1">
    <inertial>
      <origin rpy="0 0 0" xyz="0 -0.03 0.12"/>
      <mass value="3.4525"/>
      <inertia ixx="0.02183" ixy="0" ixz="0" iyy="0.007703" iyz="-0.003887" izz="0.02083"/>
    </inertial>
    <visual>
      <origin rpy="0 0 0" xyz="0 0 0.0075"/>
      <geometry>
        <mesh filename="package://iiwa_description/meshes/iiwa7/visual/link_1.obj"/>
      </geometry>
      <material name="Orange"/>
    </visual>
    <collision>
      <origin rpy="0 0 0" xyz="0 0 0.0075"/>
      <geometry>
        <mesh filename="package://iiwa_description/meshes/iiwa7/collision/link_1.obj"/>
      </geometry>
      <material name="Orange"/>
    </collision>
  </link>
  <joint name="iiwa_joint_2" type="revolute">
    <parent link="iiwa_link_1"/>
    <child link="iiwa_link_2"/>
    <origin rpy="1.5707963267948966   0 3.141592653589793" xyz="0 0 0.19"/>
    <axis xyz="0 0 1"/>
    <limit effort="300" lower="-2.0943951023931953" upper="2.0943951023931953" velocity="10"/>
    <safety_controller k_position="100" k_velocity="2" soft_lower_limit="-2.0594885173533086" soft_upper_limit="2.0594885173533086"/>
    <dynamics damping="0.5"/>
  </joint>
  <link name="iiwa_link_2">
    <inertial>
      <origin rpy="0 0 0" xyz="0.0003 0.059 0.042"/>
      <mass value="3.4821"/>
      <inertia ixx="0.02076" ixy="0" ixz="-0.003626" iyy="0.02179" iyz="0" izz="0.00779"/>
    </inertial>
    <visual>
      <origin rpy="0 0 0" xyz="0 0 0"/>
      <geometry>
        <mesh filename="package://iiwa_description/meshes/iiwa7/visual/link_2.obj"/>
      </geometry>
      <material name="Orange"/>
    </visual>
    <collision>
      <origin rpy="0 0 0" xyz="0 0 0"/>
      <geometry>
        <mesh filename="package://iiwa_description/meshes/iiwa7/collision/link_2.obj"/>
      </geometry>
      <material name="Orange"/>
    </collision>
  </link>
  <joint name="iiwa_joint_3" type="revolute">
    <parent link="iiwa_link_2"/>
    <child link="iiwa_link_3"/>
    <origin rpy="1.5707963267948966 0 3.141592653589793" xyz="0 0.21 0"/>
    <axis xyz="0 0 1"/>
    <limit effort="300" lower="-2.9670597283903604" upper="2.9670597283903604" velocity="10"/>
    <safety_controller k_position="100" k_velocity="2" soft_lower_limit="-2.9321531433504737" soft_upper_limit="2.9321531433504737"/>
    <dynamics damping="0.5"/>
  </joint>
  <link name="iiwa_link_3">
    <inertial>
      <origin rpy="0 0 0" xyz="0 0.03 0.13"/>
      <mass value="4.05623"/>
      <inertia ixx="0.03204" ixy="0" ixz="0" iyy="0.00972" iyz="0.006227" izz="0.03042"/>
    </inertial>
    <visual>
      <origin rpy="0 0 0" xyz="0 0 -0.026"/>
      <geometry>
        <mesh filename="package://iiwa_description/meshes/iiwa7/visual/link_3.obj"/>
      </geometry>
      <material name="Orange"/>
    </visual>
    <collision>
      <origin rpy="0 0 0" xyz="0 0 -0.026"/>
      <geometry>
        <mesh filename="package://iiwa_description/meshes/iiwa7/collision/link_3.obj"/>
      </geometry>
      <material name="Orange"/>
    </collision>
  </link>
  <joint name="iiwa_joint_4" type="revolute">
    <parent link="iiwa_link_3"/>
    <child link="iiwa_link_4"/>
    <origin rpy="1.5707963267948966 0 0" xyz="0 0 0.19"/>
    <axis xyz="0 0 1"/>
    <limit effort="300" lower="-2.0943951023931953" upper="2.0943951023931953" velocity="10"/>
    <safety_controller k_position="100" k_velocity="2" soft_lower_limit="-2.0594885173533086" soft_upper_limit="2.0594885173533086"/>
    <dynamics damping="0.5"/>
  </joint>
  <link name="iiwa_link_4">
    <inertial>
      <origin rpy="0 0 0" xyz="0 0.067 0.034"/>
      <mass value="3.4822"/>
      <inertia ixx="0.02178" ixy="0" ixz="0" iyy="0.02075" iyz="-0.003625" izz="0.007785"/>
    </inertial>
    <visual>
      <origin rpy="0 0 0" xyz="0 0 0"/>
      <geometry>
        <mesh filename="package://iiwa_description/meshes/iiwa7/visual/link_4.obj"/>
      </geometry>
      <material name="Orange"/>
    </visual>
    <collision>
      <origin rpy="0 0 0" xyz="0 0 0"/>
      <geometry>
        <mesh filename="package://iiwa_description/meshes/iiwa7/collision/link_4.obj"/>
      </geometry>
      <material name="Orange"/>
    </collision>
  </link>
  <joint name="iiwa_joint_5" type="revolute">
    <parent link="iiwa_link_4"/>
    <child link="iiwa_link_5"/>
    <origin rpy="-1.5707963267948966 3.141592653589793 0" xyz="0 0.21 0"/>
    <axis xyz="0 0 1"/>
    <limit effort="300" lower="-2.9670597283903604" upper="2.9670597283903604" velocity="10"/>
    <safety_controller k_position="100" k_velocity="2" soft_lower_limit="-2.9321531433504737" soft_upper_limit="2.9321531433504737"/>
    <dynamics damping="0.5"/>
  </joint>
  <link name="iiwa_link_5">
    <inertial>
      <origin rpy="0 0 0" xyz="0.0001 0.021 0.076"/>
      <mass value="2.1633"/>
      <inertia ixx="0.01287" ixy="0" ixz="0" iyy="0.005708" iyz="-0.003946" izz="0.01112"/>
    </inertial>
    <visual>
      <origin rpy="0 0 0" xyz="0 0 -0.026"/>
      <geometry>
        <mesh filename="package://iiwa_description/meshes/iiwa7/visual/link_5.obj"/>
      </geometry>
      <material name="Orange"/>
    </visual>
    <collision>
      <origin rpy="0 0 0" xyz="0 0 -0.026"/>
      <geometry>
        <mesh filename="package://iiwa_description/meshes/iiwa7/collision/link_5.obj"/>
      </geometry>
      <material name="Orange"/>
    </collision>
  </link>
  <joint name="iiwa_joint_6" type="revolute">
    <parent link="iiwa_link_5"/>
    <child link="iiwa_link_6"/>
    <origin rpy="1.5707963267948966 0 0" xyz="0 0.06070 0.19"/>
    <axis xyz="0 0 1"/>
    <limit effort="300" lower="-2.0943951023931953" upper="2.0943951023931953" velocity="10"/>
    <safety_controller k_position="100" k_velocity="2" soft_lower_limit="-2.0594885173533086" soft_upper_limit="2.0594885173533086"/>
    <dynamics damping="0.5"/>
  </joint>
  <link name="iiwa_link_6">
    <inertial>
      <origin rpy="0 0 0" xyz="0 0.0006 0.0004"/>
      <mass value="2.3466"/>
      <inertia ixx="0.006509" ixy="0" ixz="0" iyy="0.006259" iyz="0.00031891" izz="0.004527"/>
    </inertial>
    <visual>
      <origin rpy="0 0 0" xyz="0 0 0"/>
      <geometry>
        <mesh filename="package://iiwa_description/meshes/iiwa7/visual/link_6.obj"/>
      </geometry>
      <material name="Orange"/>
    </visual>
    <collision>
      <origin rpy="0 0 0" xyz="0 0 0"/>
      <geometry>
        <mesh filename="package://iiwa_description/meshes/iiwa7/collision/link_6.obj"/>
      </geometry>
      <material name="Orange"/>
    </collision>
  </link>
  <joint name="iiwa_joint_7" type="revolute">
    <parent link="iiwa_link_6"/>
    <child link="iiwa_link_7"/>
    <origin rpy="-1.5707963267948966 3.141592653589793 0" xyz="0 0.081 0.06070"/>
    <axis xyz="0 0 1"/>
    <limit effort="300" lower="-3.0543261909900763" upper="3.0543261909900763" velocity="10"/>
    <safety_controller k_position="100" k_velocity="2" soft_lower_limit="-3.01941960595019" soft_upper_limit="3.01941960595019"/>
    <dynamics damping="0.5"/>
  </joint>
  <link name="iiwa_link_7">
    <inertial>
      <origin rpy="0 0 0" xyz="0 0 0.02"/>
      <mass value="3.129"/>
      <inertia ixx="0.01464" ixy="0.0005912" ixz="0" iyy="0.01465" iyz="0" izz="0.002872"/>
    </inertial>
    <visual>
      <origin rpy="0 0 0" xyz="0 0 -0.0005"/>
      <geometry>
        <mesh filename="package://iiwa_description/meshes/iiwa7/visual/link_7.obj"/>
      </geometry>
      <material name="Grey"/>
    </visual>
    <collision>
      <origin rpy="0 0 0" xyz="0 0 -0.0005"/>
      <geometry>
        <mesh filename="package://iiwa_description/meshes/iiwa7/collision/link_7.obj"/>
      </geometry>
      <material name="Grey"/>
    </collision>
  </link>
  <joint name="iiwa_joint_ee" type="fixed">
    <parent link="iiwa_link_7"/>
    <child link="iiwa_link_ee"/>
    <origin rpy="0 0 0" xyz="0 0 0.045"/>
  </joint>
  <link name="iiwa_link_ee">
      <inertial>
      <origin rpy="0 0 0" xyz="0 0 0"/>
      <mass value="0"/>
      <inertia ixx="0" ixy="0" ixz="0" iyy="0" iyz="0" izz="0"/>
    </inertial>
  </link>
  <joint name="hand_joint" type="fixed">
    <origin rpy="0 0 1.57" xyz="0 0 0"/>
    <parent link="iiwa_link_ee"/>
    <child link="hand_base_link"/>
  </joint>
  <link name="hand_base_link">
    <inertial>
      <origin rpy="0 0 0" xyz="0 0 0"/>
      <mass value="0"/>
      <inertia ixx="0" ixy="0" ixz="0" iyy="0" iyz="0" izz="0"/>
    </inertial>
  </link>
  <link name="table1">
    <inertial>
      <mass value="10.0"/>
      <inertia ixx="1.25" ixy="0.00" ixz="0.0" iyy="2.24" iyz="0.0" izz="2.2"/>
    </inertial>
    <visual>
      <geometry>
        <mesh filename="package://bullet_ros_kuka/meshes/visual/table1.obj"/>
      </geometry>
      <material name="Orange"/>
      <origin rpy="0 0 0" xyz="0 0 -0.44"/>
    </visual>
    <collision>
      <geometry>
        <mesh filename="package://bullet_ros_kuka/meshes/collision/table1.obj"/>
      </geometry>
      <material name="Red"/>
      <origin rpy="0 0 0" xyz="0 0 -0.44"/>
    </collision>
  </link>
  <joint name="table1_joint" type="fixed">
    <origin rpy="0 0 0" xyz="0.4 0.0 0.05"/>
    <!--May be too harsh, change to lower in Z if you want the robot to go lower-->
    <parent link="world"/>
    <child link="table1"/>
  </joint>
  <link name="table1_mount">
    <inertial>
      <origin rpy="0 0 0" xyz="0 0 0"/>
      <mass value="0"/>
      <inertia ixx="0" ixy="0" ixz="0" iyy="0" iyz="0" izz="0"/>
    </inertial>
  </link>
  <joint name="table1_mount_joint" type="fixed">
    <origin rpy="0 0 0" xyz="-0.4625 0 0"/>
    <parent link="table1"/>
    <child link="table1_mount"/>
  </joint>
  <joint name="bh_base_joint" type="fixed">
    <origin rpy="0 0 0" xyz="0 0 0"/>
    <parent link="hand_base_link"/>
    <child link="bh_base_link"/>
  </joint>
  <!-- HAND BASE_LINK (RED) -->
  <link name="bh_base_link">
    <inertial>
      <mass value="0.9"/>
      <origin xyz="0 0 0"/>
      <inertia ixx="1.0" ixy="0.0" ixz="0.0" iyy="1.0" iyz="0.0" izz="1.0"/>
    </inertial>
    <visual>
      <origin rpy="0 0 0" xyz="0 0 0"/>
      <geometry>
        <mesh filename="package://barrett_hand/meshes/palm_280.obj"/>
      </geometry>
      <material name="Grey">
        <color rgba="0.75 0.75 0.75 1.0"/>
      </material>
    </visual>
    <collision>
      <origin rpy="0 0 0 " xyz="0 0 0"/>
      <geometry>
        <mesh filename="package://barrett_hand/meshes/palm_280.obj"/>
      </geometry>
      <contact_coefficients kd="1.0" kp="1000.0" mu="0"/>
    </collision>
  </link>
  <!-- finger 3 -->
  <!-- finger 32 link -->
  <link name="bh_finger_32_link">
    <inertial>
      <mass value="0.01"/>
      <origin rpy="0 0 0" xyz="0 0 0"/>
      <inertia ixx="0.01" ixy="0" ixz="0" iyy="0.01" iyz="0" izz="0.01"/>
    </inertial>
    <visual>
      <origin rpy="0 0 0" xyz="0 0 0"/>
      <geometry>
        <mesh filename="package://barrett_hand/meshes/finger_32.obj"/>
      </geometry>
      <material name="Blue"/>
    </visual>
    <collision>
      <origin rpy="0 0 0" xyz="0 0 0"/>
      <geometry>
        <mesh filename="package://barrett_hand/meshes/finger_32.obj"/>
      </geometry>
      <contact_coefficients kd="1.0" kp="1000.0" mu="0"/>
    </collision>
  </link>
  <!-- joint between BH_finger_31_link and BH_finger_32_link -->
  <joint name="bh_j32_joint" type="revolute">
    <parent link="bh_base_link"/>
    <child link="bh_finger_32_link"/>
    <origin rpy="1.5708 0 1.5708" xyz="0 -0.05 0.0754"/>
    <axis xyz="0 0 -1"/>
    <limit effort="30.0" lower="0.0" upper="2.44" velocity="2.0"/>
  </joint>
  <!-- finger 33 link -->
  <link name="bh_finger_33_link">
    <inertial>
      <mass value="0.01"/>
      <origin rpy="0 0 0" xyz="0 0 0"/>
      <inertia ixx="0.01" ixy="0" ixz="0" iyy="0.01" iyz="0" izz="0.01"/>
    </inertial>
    <visual>
      <origin rpy="0 0 0" xyz="0 0 0"/>
      <geometry>
        <mesh filename="package://barrett_hand/meshes/finger_tip_33.obj"/>
      </geometry>
      <material name="Blue"/>
    </visual>
    <collision>
      <origin rpy="0 0 0" xyz="0 0 0"/>
      <geometry>
        <mesh filename="package://barrett_hand/meshes/finger_tip_33.obj"/>
      </geometry>
      <contact_coefficients kd="1.0" kp="1000.0" mu="0"/>
    </collision>
  </link>
  <!-- joint between BH_finger_32_link and BH_finger_33_link -->
  <joint name="bh_j33_joint" type="revolute">
    <parent link="bh_finger_32_link"/>
    <child link="bh_finger_33_link"/>
    <origin rpy="0 0 0" xyz="-0.069936 0.003 0"/>
    <axis xyz="0 0 -1"/>
    <mimic joint="bh_j32_joint" multiplier="0.3442622950819672"/>
    <limit effort="30.0" lower="0.0" upper="0.84" velocity="2.0"/>
  </joint>
  <!-- finger 1 -->
  <!-- finger 11 link -->
  <link name="bh_finger_11_link">
    <inertial>
      <mass value="0.01"/>
      <origin rpy="0 0 0" xyz="-0.046 0 0"/>
      <inertia ixx="0.01" ixy="0" ixz="0" iyy="0.01" iyz="0" izz="0.01"/>
    </inertial>
    <visual>
      <origin rpy="0 0 0" xyz="0 0 0"/>
      <geometry>
        <mesh filename="package://barrett_hand/meshes/knuckle.obj"/>
      </geometry>
      <material name="Green"/>
    </visual>
    <collision>
      <origin rpy="0 0 0" xyz="0 0 0"/>
      <geometry>
        <mesh filename="package://barrett_hand/meshes/knuckle.obj"/>
      </geometry>
    </collision>
  </link>
  <!-- joint between BH_palm_link and BH_finger_11_link -->
  <joint name="bh_j11_joint" type="revolute">
    <parent link="bh_base_link"/>
    <child link="bh_finger_11_link"/>
    <origin rpy="0 0 -1.5708" xyz="0.025 0 0.0415"/>
    <axis xyz="0 0 -1"/>
    <limit effort="30.0" lower="0" upper="3.1416" velocity="2.0"/>
  </joint>
  <!-- finger 12 link -->
  <link name="bh_finger_12_link">
    <inertial>
      <mass value="0.01"/>
      <origin rpy="0 0 0" xyz="0 0 0"/>
      <inertia ixx="0.01" ixy="0" ixz="0" iyy="0.01" iyz="0" izz="0.01"/>
    </inertial>
    <visual>
      <origin rpy="0 0 0" xyz="0 0 0"/>
      <geometry>
        <mesh filename="package://barrett_hand/meshes/finger_12.obj"/>
      </geometry>
      <material name="Blue"/>
    </visual>
    <collision>
      <origin rpy="0 0 0" xyz="0 0 0"/>
      <geometry>
        <mesh filename="package://barrett_hand/meshes/finger_12.obj"/>
      </geometry>
      <contact_coefficients kd="1.0" kp="1000.0" mu="0"/>
    </collision>
  </link>
  <!-- joint between BH_finger_11_link and BH_finger_12_link -->
  <joint name="bh_j12_joint" type="revolute">
    <parent link="bh_finger_11_link"/>
    <child link="bh_finger_12_link"/>
    <origin rpy="1.5708 0 0" xyz="-0.05 0 0.0339"/>
    <axis xyz="0 0 -1"/>
    <limit effort="30.0" lower="0.0" upper="2.44" velocity="2.0"/>
  </joint>
  <!-- finger 13 link -->
  <link name="bh_finger_13_link">
    <inertial>
      <mass value="0.01"/>
      <origin rpy="0 0 0" xyz="0 0 0"/>
      <inertia ixx="0.01" ixy="0" ixz="0" iyy="0.01" iyz="0" izz="0.01"/>
    </inertial>
    <visual>
      <origin rpy="0 0 0" xyz="0 0 0"/>
      <geometry>
        <mesh filename="package://barrett_hand/meshes/finger_tip_13.obj"/>
      </geometry>
      <material name="Blue"/>
    </visual>
    <collision>
      <origin rpy="0 0 0" xyz="0 0 0"/>
      <geometry>
        <mesh filename="package://barrett_hand/meshes/finger_tip_13.obj"/>
      </geometry>
      <contact_coefficients kd="1.0" kp="1000.0" mu="0"/>
    </collision>
  </link>
  <!-- joint between BH_finger_12_link and BH_finger_13_link -->
  <joint name="bh_j13_joint" type="revolute">
    <parent link="bh_finger_12_link"/>
    <child link="bh_finger_13_link"/>
    <origin rpy="0 0 0" xyz="-0.069936 0.003 0"/>
    <axis xyz="0 0 -1"/>
    <mimic joint="bh_j12_joint" multiplier="0.3442622950819672"/>
    <limit effort="30.0" lower="0.0" upper="0.84" velocity="2.0"/>
  </joint>
  <!-- finger 2 -->
  <!-- finger 21 link -->
  <link name="bh_finger_21_link">
    <inertial>
      <mass value="0.01"/>
      <origin rpy="0 0 0" xyz="-0.046 0 0"/>
      <inertia ixx="0.01" ixy="0" ixz="0" iyy="0.01" iyz="0" izz="0.01"/>
    </inertial>
    <visual>
      <origin rpy="0 0 0" xyz="0 0 0"/>
      <geometry>
        <mesh filename="package://barrett_hand/meshes/knuckle_2.obj"/>
      </geometry>
      <material name="Green"/>
    </visual>
    <collision>
      <origin rpy="0 0 0" xyz="0 0 0"/>
      <geometry>
        <mesh filename="package://barrett_hand/meshes/knuckle_2.obj"/>
      </geometry>
    </collision>
  </link>
  <!-- joint between BH_palm_link and BH_finger_21_link -->
  <joint name="bh_j21_joint" type="revolute">
    <parent link="bh_base_link"/>
    <child link="bh_finger_21_link"/>
    <origin rpy="0 0 -1.5708" xyz="-0.025 0 0.0415"/>
    <axis xyz="0 0 1"/>
    <mimic joint="bh_j11_joint" multiplier="1"/>
    <limit effort="30.0" lower="0" upper="3.1416" velocity="2.0"/>
  </joint>
  <!-- finger 12 link -->
  <link name="bh_finger_22_link">
    <inertial>
      <mass value="0.01"/>
      <origin rpy="0 0 0" xyz="0 0 0"/>
      <inertia ixx="0.01" ixy="0" ixz="0" iyy="0.01" iyz="0" izz="0.01"/>
    </inertial>
    <visual>
      <origin rpy="0 0 0" xyz="0 0 0"/>
      <geometry>
        <mesh filename="package://barrett_hand/meshes/finger_22.obj"/>
      </geometry>
      <material name="Blue"/>
    </visual>
    <collision>
      <origin rpy="0 0 0" xyz="0 0 0"/>
      <geometry>
        <mesh filename="package://barrett_hand/meshes/finger_22.obj"/>
      </geometry>
      <contact_coefficients kd="1.0" kp="1000.0" mu="0"/>
    </collision>
  </link>
  <!-- joint between BH_finger_21_link and BH_finger_22_link -->
  <joint name="bh_j22_joint" type="revolute">
    <parent link="bh_finger_21_link"/>
    <child link="bh_finger_22_link"/>
    <origin rpy="1.5708 -8.8281E-17 0" xyz="-0.05 0 0.0339"/>
    <axis xyz="0 0 -1"/>
    <limit effort="30.0" lower="0.0" upper="2.44" velocity="2.0"/>
  </joint>
  <!-- finger 23 link -->
  <link name="bh_finger_23_link">
    <inertial>
      <mass value="0.01"/>
      <origin rpy="0 0 0" xyz="0 0 0"/>
      <inertia ixx="0.01" ixy="0" ixz="0" iyy="0.01" iyz="0" izz="0.01"/>
    </inertial>
    <visual>
      <origin rpy="0 0 0" xyz="0 0 0"/>
      <geometry>
        <mesh filename="package://barrett_hand/meshes/finger_tip_23.obj"/>
      </geometry>
      <material name="Blue"/>
    </visual>
    <collision>
      <origin rpy="0 0 0" xyz="0 0 0"/>
      <geometry>
        <mesh filename="package://barrett_hand/meshes/finger_tip_23.obj"/>
      </geometry>
      <contact_coefficients kd="1.0" kp="1000.0" mu="0"/>
    </collision>
  </link>
  <!-- joint between BH_finger_22_link and BH_finger_23_link -->
  <joint name="bh_j23_joint" type="revolute">
    <parent link="bh_finger_22_link"/>
    <child link="bh_finger_23_link"/>
    <origin rpy="0 0 0" xyz="-0.069936 0.003 0"/>
    <axis xyz="0 0 -1"/>
    <mimic joint="bh_j22_joint" multiplier="0.3442622950819672"/>
    <limit effort="30.0" lower="0.0" upper="0.84" velocity="2.0"/>
  </joint>
</robot>

