<?xml version="1.0"?>
<robot name="box_circle_robot">

    <!-- Link: Box -->
    <link name="base">
        <visual>
            <geometry>
                <box size="0.1 0.1 0.05"/>
            </geometry>
            <origin xyz="0 0 0" rpy="0 0 0"/>
            <material name="gray">
                <color rgba="0.6 0.6 0.6 1.0"/>
            </material>
        </visual>
        <collision>
            <geometry>
                <box size="0.1 0.1 0.05"/>
            </geometry>
            <origin xyz="0 0 0" rpy="0 0 0"/>
        </collision>
        <inertial>
            <mass value="2.5"/>
            <origin xyz="0 0 0"/>
            <inertia ixx="0" iyy="0" izz="0" ixy="0" ixz="0" iyz="0"/>
        </inertial>
    </link>

    <!-- Link: Circle -->
    <link name="circle">
        <visual>
            <geometry>
                <cylinder radius="0.0425" length="0.01"/>
            </geometry>
            <origin xyz="0 0 0.0575" rpy="0 0 0"/>
            <material name="red">
                <color rgba="1 0 0 1.0"/>
            </material>
        </visual>
        <collision>
            <geometry>
                <cylinder radius="0.0425" length="0.01"/>
            </geometry>
            <origin xyz="0 0 0.0575" rpy="0 0 0"/>
        </collision>
        <inertial>
            <mass value="1"/>
            <origin xyz="0 0 0"/>
            <inertia ixx="0" iyy="0" izz="0" ixy="0" ixz="0" iyz="0"/>
        </inertial>
    </link>

    <!-- Prismatic Joint -->
    <joint name="prismatic_joint" type="prismatic">
        <parent link="base"/>
        <child link="circle"/>
        <origin xyz="0 0 0.0575"/>
        <axis xyz="0 0 1"/>
        <limit lower="-0.05" upper="0" effort="10.0" velocity="1"/>
        <dynamics damping="0" friction="0"/>
    </joint>

  <link name="world">
    <inertial>
      <mass value="0"/>
      <inertia ixx="0.0" ixy="0.0" ixz="0.0" iyy="0.0" iyz="0.0" izz="0.0"/>
    </inertial>
  </link>
  <joint name="fixed_joint_1" type="fixed">
    <parent link="world"/>
    <child link="base"/>
  </joint>
</robot>